# 异常
在运行时处理所有可能发生的情况，当不正常的事情发生，提供处理机制
当读取文件时,下面的每一步都可能发生错误
- open the file
- determine its size
- allocate that much memory
- read the file into memory
- close the file

## c语言处理异常的方式
在函数处理出错时，c语言函数会通过返回一个特殊值表示函数内部的处理状况<br/>
这样做的坏处是
- 将错误状态和返回值混在一起，需要先检查该函数的返回值，不能直接参与运算
- 需要大量嵌套的if-else语句来判断，程序可读性差


        errorCodeType readFile{
            initialize errorCode = 0;
            open the filel
            if (theFilesOpen)
            {
                determine its size;
                if (gotEnoughMemory)
                {
                    allocate that much memory;
                    if (gotEnoughMemory)
                    {
                        read the file into memory;
                        if (readFailed){
                            errorCode = -1;
                        }
                    }
                    else{
                            errorCode = -2;
                    }
                }
                else{
                    errorCode = -3;
                }
                close the file;
                if (theFILEDidntClose && errorCode == 0)
                {
                    errorCode = -4;
                }
                else{
                    errorCode = errorCode and -4;
                }
            }
            else {
                errorCode = -5;
            }
            return errorCode;
        }


## 使用 c++ exception
> 当问题发生的时候，程序无法继续进行，需要外界进行干预的情况，可以使用异常
- exception将程序逻辑和异常处理分开，增强了代码可读性

        try{
            open the file;
            determine its size;
            allocate that much memory;
            read the file into memory;
            close the file;
        }
        catch(fileOpenFailed)
        {
             doSomething;   
        }
        catch(sizeDeterminationFailed)
        {
             doSomething;   
        }
        catch(memoryAllocationFailed)
        {
             doSomething;   
        }
        catch(readFailed)
        {
             doSomething;   
        }
        catch(fileClosedFailed)
        {
             doSomething;   
        }

## 异常的抛出和捕获
当使用index访问vector元素发生越界问题时,抛出异常


        template<class T>
        T& Vector<T>::operator[](int index){
            if (index < 0 || index >= m_size)
            {
                // exception is raised at this point
                throw <<something>>;
            }
            return m_elements[index];
        }

    
### 什么可以被throw抛出去
c++可以抛出所有类型的对象（内置类型或者自定义类型）<br/>
- throw抛出的对象在栈中
- 一般使用类代表error<br/>
- catch的时候尽量使用引用


        class VectorIndexError {
        public:
            VectorIndexError(int index)
                :m_index(index) {}
            ~VectorIndexError(){}
            void diagnostic() const{
                std::cerr << "index:" << m_index << " out of range!\n";
            }

        private:
            std::size_t m_index;
        };

        template<class T>
        class Vector {
        public:
            Vector():m_elements(nullptr),m_size(0){}
            Vector(const std::size_t size)
                :m_size(size)
            {
                m_elements = new T[size];
            }
            ~Vector() 
            {
                if (m_elements) {
                    delete[] m_elements;
                }
            }

            T& operator[](const std::size_t& index) const
            {
                if (index < 0 || index >= m_size)
                {
                    // ① 产生exception并抛出
                    throw VectorIndexError(index);
                }
                return m_elements[index];
            }

        private:
            std::size_t m_size;
            T* m_elements;
        };

        int func()
        {
            Vector<int> a(10);
            
            // ②出现exception，继续往上抛
            return a[20];
        }

        void func2()
        {
            try{
                func();
            }
            cathc(VectorIndexError &e)
            {
                // ③将catch捕捉到的异常抛出去
                throw;
            }
        }

        int main()
        {
            try {
                // ④处理exception
                func2();

                //func2出现异常并被try-catch捕获，后续代码不再执行
                others;
            }
            catch (VectorIndexError& e)
            {
                e.diagnostic();
            }
            catch (...) {

            }

            //try-catch之后继续执行
            std::cout << "Control is here after exception" << std::endl;
        }

## 构造函数出现异常
> 构造函数调用之前，对象的内存就已经分配完毕，如果构造函数出现异常，那么对象就不会被构造，因此也不会有析构函数被调用，这时候需要手动释放内存<br>
构造函数抛异常是很麻烦的事情，尽量不要做


        class A {
        public:
            A() {
                try {

                }
                catch (...) {
                    // 抛异常之前将对象的空间释放
                    delete this;
                    throw 0;
                }
                
            }
        };

        int fun3()
        {
            A* p = new A();
            delete p;
            return 0;
        }


